<!-- Copyright 2016-2017 The MathWorks, Inc. -->

<robot name = "robot">

<material name = "red_A">
	<color rgba = "0.87 0.32 0.16 1" />
</material>

<material name = "red_B">
	<color rgba = "0.88 0.57 0.48 1" />
</material>

<material name = "gray_A">
	<color rgba = "0.3 0.3 0.3 1" />
</material>

<material name = "gray_B">
	<color rgba = "1 1 1 1" />
</material>

<!-- Trunk Start -->
<link name = "trunk">
	<inertial>
		<origin xyz = "0 0 -0.109" rpy = "0 0 0" />
		<mass value = "0.369" />
		<inertia ixx = "1.334e-3" iyy = "1.935e-3" izz = "6.712e-4" iyz = "0" ixz = "0" ixy = "0" />
	</inertial>
	
	<visual>
		<geometry>
			<mesh filename = "trunk.step" />
		</geometry>
		<material name = "red_A" />
	</visual>
</link>


<link name = "right_hip_yaw_roll">
	<inertial>
		<origin xyz = "-0.01905 0 -0.1849" rpy = "0 0 0" />
		<mass value = "0" />
		<inertia ixx = "6.712e-8" iyy = "6.712e-8" izz = "6.712e-8" iyz = "0" ixz = "0" ixy = "0" />
	</inertial>

	<visual>
		<origin rpy="0 0 3.14" xyz="-0.01005 0.0 -0.03609"/>
		<geometry>
			<mesh filename = "hip_yaw_roll.stl" />
		</geometry>
		<material name = "gray_B" />
	</visual>
</link>


<link name = "left_hip_yaw_roll">
	<inertial>
		<origin xyz = "0.01905 0 -0.1849" rpy = "0 0 0" />
		<mass value = "0" />
		<inertia ixx = "6.712e-8" iyy = "6.712e-8" izz = "6.712e-8" iyz = "0" ixz = "0" ixy = "0" />
	</inertial>

	<visual>
		<origin rpy="0 0 0" xyz="+0.01005 0.0 -0.03609"/>
		<geometry>
			<mesh filename = "hip_yaw_roll.stl" />
		</geometry>
		<material name = "gray_B" />
	</visual>
</link>

<joint name = "right_hip_sagittal" type = "continuous">
	<!-- <origin xyz = "-0.01905 0 -0.1849" rpy = "0 0 0" /> -->
	<origin xyz = "-0.032 0 -0.1849" rpy = "0 0 0" />
	<axis xyz = "0 1 0" />
	<dynamics damping = "0.001" />
	<parent link = "trunk" />
	<child link = "right_hip_yaw_roll" />
</joint>

<joint name = "left_hip_sagittal" type = "continuous">
	<!-- <origin xyz = "0.01905 0 -0.1849" rpy = "0 0 0" /> -->
	<origin xyz = "0.032 0 -0.1849" rpy = "0 0 0" />
	<axis xyz = "0 1 0" />
	<dynamics damping = "0.001" />
	<parent link = "trunk" />
	<child link = "left_hip_yaw_roll" />
</joint>

<!-- Trunk End -->


<!-- Right Leg Start -->

<link name = "right_hip_pitch_yaw">
	<inertial>
		<origin xyz = "0 0 -0.018" rpy = "0 0 0" />
		<mass value = "0" />
		<inertia ixx = "6.712e-8" iyy = "6.712e-8" izz = "6.712e-8" iyz = "0" ixz = "0" ixy = "0" />
	</inertial>

	<visual>
		<!-- <origin rpy="0 0 0" xyz="-0.018 0.0 -0.018"/> -->
		<geometry>
			<mesh filename = "hip_pitch_yaw_new.stl" />
		</geometry>
		<material name = "gray_B" />
	</visual>
</link>

<joint name = "right_hip_yaw" type = "continuous">
	<origin xyz = "-0.01005 0.0 -0.03609" rpy = "0 0 0" />
	<axis xyz = "1 0 0" />
	<dynamics damping = "0.005" />
	<parent link = "right_hip_yaw_roll" />
	<child link = "right_hip_pitch_yaw" />
</joint>

<link name = "right_upper_leg">
	<inertial>
		<origin xyz = "-0.0254 0.00 0" rpy = "0 0 0" />
		<mass value = "0.176" />
		<inertia ixx = "4.075e-4" iyy = "4.285e-4" izz = "4.997e-5" iyz = "0" ixz = "0" ixy = "0" />
	</inertial>

	<visual>
		<geometry>
			<mesh filename = "upper_leg.step" />
		</geometry>
		<material name = "gray_B" />
	</visual>
</link>

<joint name = "right_hip_pitch" type = "continuous">
	<origin xyz = "0.0254 0 -0.025" rpy = "0 0 0" />
	<axis xyz = "1 0 0" />
	<dynamics damping = "0.005" />
	<parent link = "right_hip_pitch_yaw" />
	<child link = "right_upper_leg" />
</joint>

<link name = "right_lower_leg">
	<inertial>
		<origin xyz = "0.000 0.00 0" rpy = "0 0 0" />
		<mass value = "0.161" />
		<inertia ixx = "3.775e-4" iyy = "3.872e-4" izz = "3.398e-5" iyz = "0" ixz = "0" ixy = "0" />
	</inertial>

	<visual>
		<geometry>
			<mesh filename = "lower_leg.step" />
		</geometry>
		<material name = "gray_B" />
	</visual>
</link>

<joint name = "right_knee" type = "continuous">
	<origin xyz = "-0.0255 0 -0.1043" rpy = "0 0 0" />
	<axis xyz = "1 0 0" />
	<dynamics damping = "0.005" />
	<parent link = "right_upper_leg" />
	<child link = "right_lower_leg" />
</joint>


<link name = "right_foot_joint">
	<inertial>
		<origin xyz = "0 0 0" rpy = "0 0 0" />
		<mass value = "0.0" />
		<inertia ixx = "6.712e-20" iyy = "6.712e-20" izz = "6.712e-20" iyz = "0" ixz = "0" ixy = "0" />
	</inertial>

	<visual>
		<geometry>
			<mesh filename = "foot_joint_new.stl" />
		</geometry>
		<material name = "gray_A" />
	</visual>
</link>

<joint name = "right_ankle_pitch" type = "continuous">
	<origin xyz = "0 0.0 -0.1043" rpy = "0 0 0" />
	<axis xyz = "1 0 0" />
	<dynamics damping = "0.005" />
	<parent link = "right_lower_leg" />
	<child link = "right_foot_joint" />
</joint>


<link name = "right_foot_floor">
	<inertial>
		<origin xyz = "0 -0.013 -0.011" rpy = "0 0 0" />
		<mass value = "0.126" />
		<inertia ixx = "1.256e-4" iyy = "3.787e-5" izz = "1.145e-4" iyz = "-2.238e-5" ixz = "0" ixy = "0" />
	</inertial>

	<visual>
		<geometry>
			<mesh filename = "foot_floor_new.stl" />
		</geometry>
		<material name = "gray_A" />
	</visual>
</link>

<joint name = "right_ankle_roll" type = "continuous">
	<origin xyz = "0 0.0022 -0.0167" rpy = "0 0 0" />
	<axis xyz = "0 1 0" />
	<dynamics damping = "0.005" />
	<parent link = "right_foot_joint" />
	<child link = "right_foot_floor" />
</joint>



<!-- Right Leg End -->


<!-- Left Leg Start -->

<link name = "left_hip_pitch_yaw">
	<inertial>
		<origin xyz = "0 0 -0.018" rpy = "0 0 0" />
		<mass value = "0" />
		<inertia ixx = "6.712e-8" iyy = "6.712e-8" izz = "6.712e-8" iyz = "0" ixz = "0" ixy = "0" />
	</inertial>

	<visual>
		<!-- <origin rpy="0 0 3.14" xyz="+0.018 0.0 -0.018"/> -->
		<geometry>
			<mesh filename = "hip_pitch_yaw_new.stl" />
		</geometry>
		<material name = "gray_B" />
	</visual>
</link>

<joint name = "left_hip_yaw" type = "continuous">
	<origin xyz = "0.01005 0.0 -0.03609" rpy = "0 0 0" />
	<axis xyz = "1 0 0" />
	<dynamics damping = "0.005" />
	<parent link = "left_hip_yaw_roll" />
	<child link = "left_hip_pitch_yaw" />
</joint>

<link name = "left_upper_leg">
	<inertial>
		<origin xyz = "0.0254 0.00 0" rpy = "0 0 0" />
		<mass value = "0.176" />
		<inertia ixx = "4.075e-4" iyy = "4.285e-4" izz = "4.997e-5" iyz = "0" ixz = "0" ixy = "0" />
	</inertial>

	<visual>
		<origin rpy="0 0 3.14" xyz="0 0.0 0"/>
		<geometry>
			<mesh filename = "upper_leg.step" />
		</geometry>
		<material name = "gray_B" />
	</visual>
</link>

<joint name = "left_hip_pitch" type = "continuous">
	<origin xyz = "-0.0254 0 -0.025" rpy = "0 0 0" />
	<axis xyz = "1 0 0" />
	<dynamics damping = "0.005" />
	<parent link = "left_hip_pitch_yaw" />
	<child link = "left_upper_leg" />
</joint>

<link name = "left_lower_leg">
	<inertial>
		<origin xyz = "0.000 0.00 0" rpy = "0 0 0" />
		<mass value = "0.161" />
		<inertia ixx = "3.775e-4" iyy = "3.872e-4" izz = "3.398e-5" iyz = "0" ixz = "0" ixy = "0" />
	</inertial>

	<visual>
		<geometry>
			<mesh filename = "lower_leg.step" />
		</geometry>
		<material name = "gray_B" />
	</visual>
</link>

<joint name = "left_knee" type = "continuous">
	<origin xyz = "0.0255 0 -0.1043" rpy = "0 0 0" />
	<axis xyz = "1 0 0" />
	<dynamics damping = "0.005" />
	<parent link = "left_upper_leg" />
	<child link = "left_lower_leg" />
</joint>

<link name = "left_foot_joint">
	<inertial>
		<origin xyz = "0 0 0" rpy = "0 0 0" />
		<mass value = "0.0" />
		<inertia ixx = "6.712e-20" iyy = "6.712e-20" izz = "6.712e-20" iyz = "0" ixz = "0" ixy = "0" />
	</inertial>

	<visual>
		<geometry>
			<mesh filename = "foot_joint_new.stl" />
		</geometry>
		<material name = "gray_A" />
	</visual>
</link>

<joint name = "left_ankle_pitch" type = "continuous">
	<origin xyz = "0 0.0 -0.1043" rpy = "0 0 0" />
	<axis xyz = "1 0 0" />
	<dynamics damping = "0.005" />
	<parent link = "left_lower_leg" />
	<child link = "left_foot_joint" />
</joint>


<link name = "left_foot_floor">
	<inertial>
		<origin xyz = "0 -0.013 -0.011" rpy = "0 0 0" />
		<mass value = "0.126" />
		<inertia ixx = "1.256e-4" iyy = "3.787e-5" izz = "1.145e-4" iyz = "-2.238e-5" ixz = "0" ixy = "0" />
	</inertial>

	<visual>
		<geometry>
			<mesh filename = "foot_floor_new.stl" />
		</geometry>
		<material name = "gray_A" />
	</visual>
</link>

<joint name = "left_ankle_roll" type = "continuous">
	<origin xyz = "0 0.0022 -0.0167" rpy = "0 0 0" />
	<axis xyz = "0 1 0" />
	<dynamics damping = "0.005" />
	<parent link = "left_foot_joint" />
	<child link = "left_foot_floor" />
</joint>



<!-- Left Leg End -->

<link name = "waistline">
	<inertial>
		<origin xyz = "0 0 0" rpy = "0 0 0" />
		<mass value = "0.311" />
		<inertia ixx = "1.008e-4" iyy = "2.751e-4" izz = "3.104e-4" iyz = "0" ixz = "0" ixy = "0" />
	</inertial>
	
	<visual>
		<geometry>
			<mesh filename = "waistline.step" />
		</geometry>
		<material name = "color_A" />
	</visual>
</link>

<joint name = "trunk_waistline_fixed" type = "fixed">
	<origin xyz = "0 0 -0.1849" rpy = "0 0 0" />
	<parent link = "trunk" />
	<child link = "waistline" />
</joint>

<link name = "shoulder_line">
	<inertial>
		<origin xyz = "0 0 0.003" rpy = "0 0 0" />
		<mass value = "0.049" />
		<inertia ixx = "1.753e-5" iyy = "4.884e-5" izz = "4.634e-5" iyz = "0" ixz = "0" ixy = "0" />
	</inertial>
	
	<visual>
		<geometry>
			<mesh filename = "shoulder_line.step" />
		</geometry>
		<material name = "red_B" />
	</visual>
</link>

<joint name = "trunk_shoulder" type = "fixed">
	<origin xyz = "0 0 -0.0399" rpy = "0 0 0" />
	<axis xyz = "1 0 0" />
	<dynamics damping = "0.05" />
	<parent link = "trunk" />
	<child link = "shoulder_line" />
</joint>


<link name = "neck">
	<inertial>
		<origin xyz = "0 0 0.019" rpy = "0 0 0" />
		<mass value = "0.021" />
		<inertia ixx = "6.005e-6" iyy = "8.752e-6" izz = "3.339e-6" iyz = "0" ixz = "0" ixy = "0" />
	</inertial>
	
	<visual>
		<geometry>
			<mesh filename = "neck.step" />
		</geometry>
		<material name = "gray_B" />
	</visual>
</link>

<joint name = "shoulder_neck" type = "fixed">
	<origin xyz = "0 0 0.01016" rpy = "0 0 0" />
	<axis xyz = "0 0 1" />
	<dynamics damping = "0.001" />
	<parent link = "shoulder_line" />
	<child link = "neck" />
</joint>

<link name = "head">
	<inertial>
		<origin xyz = "0 0.002 0" rpy = "0 0 0" />
		<mass value = "0.01" />
		<inertia ixx = "6.874e-6" iyy = "8.226e-6" izz = "6.992e-6" iyz = "0" ixz = "0" ixy = "0" />
	</inertial>
	
	<visual>
		<geometry>
			<mesh filename = "head.step" />
		</geometry>
		<material name = "gray_A" />
	</visual>
</link>

<link name = "cover">
	<inertial>
		<origin xyz = "0 -0.024 0" rpy = "0 0 0" />
		<mass value = "0.004" />
		<inertia ixx = "1.030e-6" iyy = "2.060e-6" izz = "1.030e-6" iyz = "0" ixz = "0" ixy = "0" />
	</inertial>
	
	<visual>
		<geometry>
			<mesh filename = "cover.step" />
		</geometry>
		<material name = "gray_B" />
	</visual>
</link>

<joint name = "neck_head" type = "fixed">
	<origin xyz = "0 0 0.06414" rpy = "0 0 0" />
	<parent link = "neck" />
	<child link = "head" />
</joint>

<joint name = "head_cover_fixed" type = "fixed">
	<origin xyz = "0 0 0" rpy = "0 0 0" />
	<parent link = "head" />
	<child link = "cover" />
</joint>

</robot>